Workbook

Sheet Produits de nettoyage (2)
B3: Direction Générale du Budget | K3: Direction Générale du Budget
B4: Inventaire stocksProduits de nettoyage | K4: Inventaire stocksProduits de nettoyage
B5: Exercice: 2024-2025
B6: Premier Trimestre | K6: Exercice: 2022-2023
B7: Pour le mois d'octobre 2024
K8: Liste des articles | L8: Stock minimum | M8: Stock initial | N8: Quantités reçues | O8: Sorties | P8: Stock actuel
B9: Produits de nettoyage | K9: Produits de nettoyage
B10: Air fresh (glade) | C10: 10 | D10: 19 | E10: 0 | F10: 5 | G10: =D10+E10-F10 -> 14 | H10: =_xlfn.IFS(G10<=0,0,G10<=C10,1,G10>=C10,2) -> 2 | K10: Air fresh (glade) | L10: 44957 | M10: 34 | N10: 0 | O10: 9 | P10: =M10+N10-O10 -> 25
B11: Acide | C11: 10 | D11: 6 | E11: 0 | F11: 0 | G11: =D11+E11-F11 -> 6 | H11: =_xlfn.IFS(G11<=0,0,G11<=C11,1,G11>=C11,2) -> 1 | J11: Air fresh (glade) | K11: Acide | L11: 44957 | M11: 3 | N11: 0 | O11: 0 | P11: =M11+N11-O11 -> 3
B12: Ajax | C12: 10 | D12: 26 | E12: 0 | F12: 8 | G12: =D12+E12-F12 -> 18 | H12: =_xlfn.IFS(G12<=0,0,G12<=C12,1,G12>=C12,2) -> 2 | J12: Acide | K12: Ajax | L12: 44957 | M12: 0 | N12: 0 | O12: 0 | P12: =M12+N12-O12 -> 0
B13: Alcool | C13: 10 | D13: 12 | E13: 0 | F13: 1 | G13: =D13+E13-F13 -> 11 | H13: =_xlfn.IFS(G13<=0,0,G13<=C13,1,G13>=C13,2) -> 2 | J13: Ajax | K13: Alcool | L13: 44957 | M13: 30 | N13: 0 | O13: 2 | P13: =M13+N13-O13 -> 28
B14: Balais (petits) | C14: 10 | D14: 3 | E14: 0 | F14: 0 | G14: =D14+E14-F14 -> 3 | H14: =_xlfn.IFS(G14<=0,0,G14<=C14,1,G14>=C14,2) -> 1 | J14: Alcool | K14: Balais (petits) | L14: 44957 | M14: 4 | N14: 0 | O14: 0 | P14: =M14+N14-O14 -> 4
B15: Balais (gros) | C15: 10 | D15: 19 | E15: 0 | F15: 2 | G15: =D15+E15-F15 -> 17 | H15: =_xlfn.IFS(G15<=0,0,G15<=C15,1,G15>=C15,2) -> 2 | J15: Balais (petits) | K15: Balais (gros) | L15: 44957 | M15: 42 | N15: 0 | O15: 2 | P15: =M15+N15-O15 -> 40
B16: Brosses | C16: 10 | D16: 0 | E16: 0 | F16: 0 | G16: =D16+E16-F16 -> 0 | H16: =_xlfn.IFS(G16<=0,0,G16<=C16,1,G16>=C16,2) -> 0 | J16: Balais (gros) | K16: Brosses | L16: 44957 | M16: 0 | N16: 0 | O16: 0 | P16: =M16+N16-O16 -> 0
B17: Baygon | C17: 10 | D17: 0 | E17: 0 | F17: 0 | G17: =D17+E17-F17 -> 0 | H17: =_xlfn.IFS(G17<=0,0,G17<=C17,1,G17>=C17,2) -> 0 | J17: Brosses | K17: Baygon | L17: 44957 | M17: 36 | N17: 0 | O17: 1 | P17: =M17+N17-O17 -> 35
B18: Clorox | C18: 10 | D18: 9 | E18: 0 | F18: 4 | G18: =D18+E18-F18 -> 5 | H18: =_xlfn.IFS(G18<=0,0,G18<=C18,1,G18>=C18,2) -> 1 | J18: Baygon | K18: Clorox | L18: 44957 | M18: 29 | N18: 0 | O18: 2 | P18: =M18+N18-O18 -> 27
B19: Eponges | C19: 10 | D19: 20 | E19: 0 | F19: 1 | G19: =D19+E19-F19 -> 19 | H19: =_xlfn.IFS(G19<=0,0,G19<=C19,1,G19>=C19,2) -> 2 | J19: Clorox | K19: Eponges | L19: 44957 | M19: 123 | N19: 0 | O19: 8 | P19: =M19+N19-O19 -> 115
B20: Fabuloso | C20: 10 | D20: 5 | E20: 0 | F20: 3 | G20: =D20+E20-F20 -> 2 | H20: =_xlfn.IFS(G20<=0,0,G20<=C20,1,G20>=C20,2) -> 1 | J20: Eponges | K20: Fabuloso | L20: 44957 | M20: 109 | N20: 0 | O20: 14 | P20: =M20+N20-O20 -> 95
B21: Gants | C21: 10 | D21: 0 | E21: 0 | F21: 0 | G21: 0 | H21: =_xlfn.IFS(G21<=0,0,G21<=C21,1,G21>=C21,2) -> 0 | J21: Fabuloso | K21: Gants | L21: 44957 | M21: 0 | N21: 0 | O21: 0 | P21: =M21+N21-O21 -> 0
B22: Huile meuble (Pledge) | C22: 10 | D22: 8 | E22: 0 | F22: 3 | G22: =D22+E22-F22 -> 5 | H22: =_xlfn.IFS(G22<=0,0,G22<=C22,1,G22>=C22,2) -> 1 | J22: Gants | K22: Huile meuble (Pledge) | L22: 44957 | M22: 32 | N22: 0 | O22: 7 | P22: =M22+N22-O22 -> 25
B23: Kleen (petit) | C23: 10 | D23: 15 | E23: 0 | F23: 0 | G23: =D23+E23-F23 -> 15 | H23: =_xlfn.IFS(G23<=0,0,G23<=C23,1,G23>=C23,2) -> 2 | J23: Huile meuble (Pledge) | K23: Kleen (petit) | L23: 44957 | M23: 28 | N23: 0 | O23: 4 | P23: =M23+N23-O23 -> 24
B24: Kleen (gros) | C24: 10 | D24: 17 | E24: 0 | F24: 2 | G24: =D24+E24-F24 -> 15 | H24: =_xlfn.IFS(G24<=0,0,G24<=C24,1,G24>=C24,2) -> 2 | J24: Kleen (petit) | K24: Kleen (gros) | L24: 44957 | M24: 13 | N24: 0 | O24: 0 | P24: =M24+N24-O24 -> 13
B25: Manche à balai (petit) | C25: 10 | D25: 3 | E25: 0 | F25: 0 | G25: =D25+E25-F25 -> 3 | H25: =_xlfn.IFS(G25<=0,0,G25<=C25,1,G25>=C25,2) -> 1 | J25: Kleen (gros) | K25: Manche à balai (petit) | L25: 44957 | M25: 5 | N25: 0 | O25: 0 | P25: =M25+N25-O25 -> 5
B26: Manche à balai/serpillère (gros) | C26: 10 | D26: 14 | E26: 0 | F26: 1 | G26: =D26+E26-F26 -> 13 | H26: =_xlfn.IFS(G26<=0,0,G26<=C26,1,G26>=C26,2) -> 2 | J26: Manche à balai (petit) | K26: Manche à balai/serpillère (gros) | L26: 44957 | M26: 47 | N26: 0 | O26: 3 | P26: =M26+N26-O26 -> 44
B27: Liquide vaisselle | C27: 10 | D27: 14 | E27: 0 | F27: 3 | G27: =D27+E27-F27 -> 11 | H27: =_xlfn.IFS(G27<=0,0,G27<=C27,1,G27>=C27,2) -> 2 | J27: Manche à balai/serpillère (gros) | K27: Liquide vaisselle | L27: 44957 | M27: 31 | N27: 0 | O27: 2 | P27: =M27+N27-O27 -> 29
B28: Liquide main | C28: 10 | D28: 5 | E28: 0 | F28: 1 | G28: =D28+E28-F28 -> 4 | H28: =_xlfn.IFS(G28<=0,0,G28<=C28,1,G28>=C28,2) -> 1 | J28: Liquide main | K28: Liquide main | L28: 44957 | M28: 0 | N28: 6 | O28: 3 | P28: =M28+N28-O28 -> 3
B29: Liquide voiture | C29: 10 | D29: 14 | E29: 0 | F29: 2 | G29: =D29+E29-F29 -> 12 | H29: =_xlfn.IFS(G29<=0,0,G29<=C29,1,G29>=C29,2) -> 2 | J29: Liquide vaisselle | K29: Liquide voiture | L29: 44957 | M29: 12 | N29: 0 | O29: 2 | P29: =M29+N29-O29 -> 10
B30: Papiers hygiéniques | C30: 100 | D30: 586 | E30: 0 | F30: 125 | G30: =D30+E30-F30 -> 461 | H30: =_xlfn.IFS(G30<=0,0,G30<=C30,1,G30>=C30,2) -> 2 | J30: Liquide voiture | K30: Papiers hygiéniques | L30: 44957 | M30: 390 | N30: 0 | O30: 130 | P30: =M30+N30-O30 -> 260
B31: Paille | C31: 10 | D31: 0 | E31: 0 | F31: 0 | G31: =D31+E31-F31 -> 0 | H31: =_xlfn.IFS(G31<=0,0,G31<=C31,1,G31>=C31,2) -> 0 | J31: Papiers hygiéniques | K31: Paille | L31: 44957 | M31: 3 | N31: 0 | O31: 0 | P31: =M31+N31-O31 -> 3
B32: Pinol | C32: 10 | D32: 22 | E32: 0 | F32: 3 | G32: =D32+E32-F32 -> 19 | H32: =_xlfn.IFS(G32<=0,0,G32<=C32,1,G32>=C32,2) -> 2 | J32: Paille | K32: Pinol | L32: 44957 | M32: 34 | N32: 0 | O32: 2 | P32: =M32+N32-O32 -> 32
B33: Pompe (toilette) | C33: 10 | D33: 0 | E33: 0 | F33: 0 | G33: =D33+E33-F33 -> 0 | H33: =_xlfn.IFS(G33<=0,0,G33<=C33,1,G33>=C33,2) -> 0 | J33: Pinol | K33: Pompe (toilette) | L33: 44957 | M33: 3 | N33: 0 | O33: 0 | P33: =M33+N33-O33 -> 3
... B40: Vitrex | C40: 10 | D40: 39 | E40: 0 | F40: 3 | G40: =D40+E40-F40 -> 36 | H40: =_xlfn.IFS(G40<=0,0,G40<=C40,1,G40>=C40,2) -> 2 | J40: Serpillères sans manche | K40: Vitrex | L40: 44957 | M40: 4 | N40: 0 | O40: 1 | P40: =M40+N40-O40 -> 3
B41: Pour le mois de novembre 2024 | J41: Vitrex
K42: Liste des articles | L42: Stock minimum | M42: Stock initial | N42: Quantités reçues | O42: Sorties | P42: Stock actuel
B43: Air fresh (glade) | C43: 10 | D43: 14 | E43: 0 | F43: =SUM(S!N13:N14) -> 2 | G43: =D43+E43-F43 -> 12 | H43: =_xlfn.IFS(G43<=0,0,G43<=C43,1,G43>=C43,2) -> 2 | K43: Air fresh (glade) | L43: 44985 | M43: 25 | N43: 0 | O43: 1 | P43: =M43+N43-O43 -> 24
B44: Acide | C44: 10 | D44: 6 | E44: 0 | F44: =SUM(S!N26) -> 1 | G44: =D44+E44-F44 -> 5 | H44: =_xlfn.IFS(G44<=0,0,G44<=C44,1,G44>=C44,2) -> 1 | K44: Acide | L44: 44985 | M44: 3 | N44: 0 | O44: 0 | P44: =M44+N44-O44 -> 3
B45: Ajax | C45: 10 | D45: 18 | E45: 0 | F45: =SUM(S!N37:N40) -> 4 | G45: =D45+E45-F45 -> 14 | H45: =_xlfn.IFS(G45<=0,0,G45<=C45,1,G45>=C45,2) -> 2 | K45: Ajax | L45: 44985 | M45: 0 | N45: 0 | O45: 0 | P45: =M45+N45-O45 -> 0
B46: Alcool | C46: 10 | D46: 11 | E46: 0 | F46: =SUM(S!N48) -> 1 | G46: =D46+E46-F46 -> 10 | H46: =_xlfn.IFS(G46<=0,0,G46<=C46,1,G46>=C46,2) -> 1 | K46: Alcool | L46: 44985 | M46: 28 | N46: 0 | O46: 2 | P46: =M46+N46-O46 -> 26
B47: Balais (petits) | C47: 10 | D47: 3 | E47: 0 | F47: =SUM(S!E73) -> 0 | G47: =D47+E47-F47 -> 3 | H47: =_xlfn.IFS(G47<=0,0,G47<=C47,1,G47>=C47,2) -> 1 | K47: Balais (petits) | L47: 44985 | M47: 4 | N47: 0 | O47: 0 | P47: =M47+N47-O47 -> 4
B48: Balais (gros) | C48: 10 | D48: 17 | E48: 0 | F48: =SUM(S!N72:N73) -> 2 | G48: =D48+E48-F48 -> 15 | H48: =_xlfn.IFS(G48<=0,0,G48<=C48,1,G48>=C48,2) -> 2 | K48: Balais (gros) | L48: 44985 | M48: 40 | N48: 0 | O48: 1 | P48: =M48+N48-O48 -> 39
...

Sheet A
B2: Direction Générale du Budget | J2: Direction Générale du Budget | R2: Direction Générale du Budget | Z2: Direction Générale du Budget | AH2: Direction Générale du Budget | AP2: Direction Générale du Budget | AX2: Direction Générale du Budget | BF2: Direction Générale du Budget | BN2: Direction Générale du Budget | BV2: Direction Générale du Budget | CD2: Direction Générale du Budget | CL2: Direction Générale du Budget
B3: Inventaire stocks fournitures | J3: Inventaire stocks fournitures | R3: Inventaire stocks fournitures | Z3: Inventaire stocks fournitures | AH3: Inventaire stocks fournitures | AP3: Inventaire stocks fournitures | AX3: Inventaire stocks fournitures | BF3: Inventaire stocks fournitures | BN3: Inventaire stocks fournitures | BV3: Inventaire stocks fournitures | CD3: Inventaire stocks fournitures | CL3: Inventaire stocks fournitures
B4: Exercice: 2024-2025 | J4: Exercice: 2024-2025 | R4: Exercice: 2024-2025 | Z4: Exercice: 2024-2025 | AH4: Exercice: 2024-2025 | AP4: Exercice: 2024-2025 | AX4: Exercice: 2024-2025 | BF4: Exercice: 2024-2025 | BN4: Exercice: 2024-2025 | BV4: Exercice: 2024-2025 | CD4: Exercice: 2024-2025 | CL4: Exercice: 2024-2025
B6: 45566 | J6: 45597 | R6: 45627 | Z6: 45658 | AH6: 45689 | AP6: 45717 | AX6: 45748 | BF6: 45778 | BN6: 45809 | BV6: 45839 | CD6: 45870 | CL6: 45536
B7: Fournitures de bureau | J7: Fournitures de bureau | R7: Fournitures de bureau | Z7: Fournitures de bureau | AH7: Fournitures de bureau | AP7: Fournitures de bureau | AX7: Fournitures de bureau | BF7: Fournitures de bureau | BN7: Fournitures de bureau | BV7: Fournitures de bureau | CD7: Fournitures de bureau | CL7: Fournitures de bureau
B9: A | J9: A | R9: A | Z9: A | AH9: A | AP9: A | AX9: A | BF9: A | BN9: A | BV9: A | CD9: A | CL9: A
B11: Adhésifs 3/4 pour dévidoir | J11: Adhésifs 3/4 pour dévidoir | R11: Adhésifs 3/4 Pour dévidoir | Z11: Adhésifs 3/4 Pour dévidoir | AH11: Adhésifs 3/4 Pour dévidoir | AP11: Adhésifs 3/4 Pour dévidoir | AX11: Adhésifs 3/4 Pour dévidoir | BF11: Adhésifs 3/4 Pour dévidoir | BN11: Adhésifs 3/4 Pour dévidoir | BV11: Adhésifs 3/4 Pour dévidoir | CD11: Adhésifs 3/4 Pour dévidoir | CL11: Adhésifs 3/4 Pour dévidoir
E12: Rentree | F12: Sortie | G12: Direction | H12: Stock | M12: Rentree | N12: Sortie | O12: Direction | P12: Stock | U12: Rentree | V12: Sortie | W12: Direction | X12: Stock | AC12: Rentree | AD12: Sortie | AE12: Direction | AF12: Stock | AK12: Rentree | AL12: Sortie | AM12: Direction | AN12: Stock | AS12: Rentree | AT12: Sortie | AU12: Direction | AV12: Stock | BA12: Rentree | BB12: Sortie | BC12: Direction | BD12: Stock | BI12: Rentree | BJ12: Sortie | BK12: Direction | BL12: Stock | BQ12: Rentree | BR12: Sortie | BS12: Direction | BT12: Stock | BY12: Rentree | BZ12: Sortie | CA12: Direction | CB12: Stock | CG12: Rentree | CH12: Sortie | CI12: Direction | CJ12: Stock | CO12: Rentree | CP12: Sortie | CQ12: Direction | CR12: Stock
B13: Stock 30 Sept.24 | E13: Unités | F13: Unités | H13: 147 | J13: Stock 31 Oct. 24 | M13: Unités | N13: Unités | P13: 147 | R13: Stock 30 Nov. 24 | U13: Unités | V13: Unités | X13: 147 | Z13: Stock 31 Déc. 24 | AC13: Unités | AD13: Unités | AF13: 147 | AH13: Stock 31 Jan. 25 | AK13: Unités | AL13: Unités | AN13: 147 | AP13: Stock 28 Fév. 25 | AS13: Unités | AT13: Unités | AV13: 147 | AX13: Stock 31 Mars. 25 | BA13: Unités | BB13: Unités | BD13: 147 | BF13: Stock 30 Avril. 25 | BI13: Unités | BJ13: Unités | BL13: 147 | BN13: Stock 31 Mai. 25 | BQ13: Unités | BR13: Unités | BT13: 147 | BV13: Stock 30 Juin. 25 | BY13: Unités | BZ13: Unités | CB13: 147 | CD13: Stock 31 Juil. 25 | CG13: Unités | CH13: Unités | CJ13: =CB13 -> 147 | CL13: Stock 31 Août. 24 | CO13: Unités | CP13: Unités | CR13: =CJ13 -> 147
H14: =SUM(H13+E14-F14) -> 147 | P14: =SUM(P13+M14-N14) -> 147 | X14: =SUM(X13+U14-V14) -> 147 | AF14: =SUM(AF13+AC14-AD14) -> 147 | AN14: =SUM(AN13+AK14-AL14) -> 147 | AV14: =SUM(AV13+AS14-AT14) -> 147 | BD14: =SUM(BD13+BA14-BB14) -> 147 | BL14: =SUM(BL13+BI14-BJ14) -> 147 | BT14: =SUM(BT13+BQ14-BR14) -> 147 | CB14: =SUM(CB13+BY14-BZ14) -> 147 | CJ14: =SUM(CJ13+CG14-CH14) -> 147 | CR14: =SUM(CR13+CO14-CP14) -> 147
H15: =SUM(H14+E15-F15) -> 147 | P15: =SUM(P14+M15-N15) -> 147 | X15: =SUM(X14+U15-V15) -> 147 | AF15: =SUM(AF14+AC15-AD15) -> 147 | AN15: =SUM(AN14+AK15-AL15) -> 147 | AV15: =SUM(AV14+AS15-AT15) -> 147 | BD15: =SUM(BD14+BA15-BB15) -> 147 | BL15: =SUM(BL14+BI15-BJ15) -> 147 | BT15: =SUM(BT14+BQ15-BR15) -> 147 | CB15: =SUM(CB14+BY15-BZ15) -> 147 | CJ15: =SUM(CJ14+CG15-CH15) -> 147 | CR15: =SUM(CR14+CO15-CP15) -> 147
H16: =SUM(H15+E16-F16) -> 147 | P16: =SUM(P15+M16-N16) -> 147 | X16: =SUM(X15+U16-V16) -> 147 | AF16: =SUM(AF15+AC16-AD16) -> 147 | AN16: =SUM(AN15+AK16-AL16) -> 147 | AV16: =SUM(AV15+AS16-AT16) -> 147 | BD16: =SUM(BD15+BA16-BB16) -> 147 | BL16: =SUM(BL15+BI16-BJ16) -> 147 | BT16: =SUM(BT15+BQ16-BR16) -> 147 | CB16: =SUM(CB15+BY16-BZ16) -> 147 | CJ16: =SUM(CJ15+CG16-CH16) -> 147 | CR16: =SUM(CR15+CO16-CP16) -> 147
B17: Agrafes pour agrafeuse | J17: Agrafes pour agrafeuse | R17: Agrafes pour agrafeuse | Z17: Agrafes pour agrafeuse | AH17: Agrafes pour agrafeuse | AP17: Agrafes pour agrafeuse | AX17: Agrafes pour agrafeuse | BF17: Agrafes pour agrafeuse | BN17: Agrafes pour agrafeuse | BV17: Agrafes pour agrafeuse | CD17: Agrafes pour agrafeuse | CL17: Agrafes pour agrafeuse
E18: Rentree | F18: Sortie | G18: Direction | H18: Stock | M18: Rentree | N18: Sortie | O18: Direction | P18: Stock | U18: Rentree | V18: Sortie | W18: Direction | X18: Stock | AC18: Rentree | AD18: Sortie | AE18: Direction | AF18: Stock | AK18: Rentree | AL18: Sortie | AM18: Direction | AN18: Stock | AS18: Rentree | AT18: Sortie | AU18: Direction | AV18: Stock | BA18: Rentree | BB18: Sortie | BC18: Direction | BD18: Stock | BI18: Rentree | BJ18: Sortie | BK18: Direction | BL18: Stock | BQ18: Rentree | BR18: Sortie | BS18: Direction | BT18: Stock | BY18: Rentree | BZ18: Sortie | CA18: Direction | CB18: Stock | CG18: Rentree | CH18: Sortie | CI18: Direction | CJ18: Stock | CO18: Rentree | CP18: Sortie | CQ18: Direction | CR18: Stock
B19: Stock 30 Sept.24 | E19: Boites | F19: Boites | H19: 149 | J19: Stock 31 Oct. 24 | M19: Boites | N19: Boites | P19: 147 | R19: Stock 30 Nov. 24 | U19: Boites | V19: Boites | X19: 147 | Z19: Stock 31 Déc. 24 | AC19: Boites | AD19: Boites | AF19: 146 | AH19: Stock 31 Jan. 25 | AK19: Boites | AL19: Boites | AN19: 144 | AP19: Stock 28 Fév. 25 | AS19: Boites | AT19: Boites | AV19: 142 | AX19: Stock 31 Mars. 25 | BA19: Boites | BB19: Boites | BD19: 142 | BF19: Stock 30 Avril. 25 | BI19: Boites | BJ19: Boites | BL19: 140 | BN19: Stock 31 Mai. 25 | BQ19: Boites | BR19: Boites | BT19: =BL23 -> 137 | BV19: Stock 30 Juin. 25 | BY19: Boites | BZ19: Boites | CB19: =BT23 -> 137 | CD19: Stock 31 Juil. 25 | CG19: Boites | CH19: Boites | CJ19: =CB23 -> 134 | CL19: Stock 31 Août. 24 | CO19: Boites | CP19: Boites | CR19: =CJ21 -> 129
B20: 45569 | E20: 0 | F20: 1 | G20: DSI | H20: =SUM(H19+E20-F20) -> 148 | P20: =SUM(P19+M20-N20) -> 147 | R20: 45629 | U20: 0 | V20: 1 | W20: DS | X20: =SUM(X19+U20-V20) -> 146 | Z20: 45664 | AC20: 0 | AD20: 1 | AE20: DAA | AF20: =SUM(AF19+AC20-AD20) -> 145 | AH20: 45702 | AK20: 0 | AL20: 1 | AM20: DGA | AN20: =SUM(AN19+AK20-AL20) -> 143 | AS20: 0 | AV20: =SUM(AV19+AS20-AT20) -> 142 | AX20: 45775 | BA20: 0 | BB20: 2 | BC20: DCB | BD20: =SUM(BD19+BA20-BB20) -> 140 | BF20: 45783 | BI20: 0 | BJ20: 1 | BK20: DG | BL20: =SUM(BL19+BI20-BJ20) -> 139 | BQ20: 0 | BT20: =SUM(BT19+BQ20-BR20) -> 137 | BV20: 45855 | BY20: 0 | BZ20: 2 | CA20: DAA | CB20: =SUM(CB19+BY20-BZ20) -> 135 | CD20: 45895 | CG20: 0 | CH20: 5 | CI20: DASIP | CJ20: =SUM(CJ19+CG20-CH20) -> 129 | CL20: 45901 | CO20: 0 | CP20: 2 | CQ20: DAA | CR20: =SUM(CR19+CO20-CP20) -> 127
B21: 45572 | E21: 0 | F21: 1 | G21: DAA | H21: =SUM(H20+E21-F21) -> 147 | P21: =SUM(P20+M21-N21) -> 147 | X21: =SUM(X20+U21-V21) -> 146 | Z21: 45680 | AC21: 0 | AD21: 1 | AE21: DS | AF21: =SUM(AF20+AC21-AD21) -> 144 | AH21: 45705 | AK21: 0 | AL21: 1 | AM21: DCB | AN21: =SUM(AN20+AK21-AL21) -> 142 | AV21: =SUM(AV20+AS21-AT21) -> 142 | BD21: =SUM(BD20+BA21-BB21) -> 140 | BF21: 45793 | BI21: 0 | BJ21: 1 | BK21: DASIP | BL21: =SUM(BL20+BI21-BJ21) -> 138 | BQ21: 0 | BT21: =SUM(BT20+BQ21-BR21) -> 137 | BV21: 45861 | BY21: 0 | BZ21: 1 | CA21: DRH | CB21: =SUM(CB20+BY21-BZ21) -> 134 | CJ21: =SUM(CJ20+CG21-CH21) -> 129 | CL21: 45904 | CO21: 0 | CP21: 1 | CQ21: DEPB | CR21: =SUM(CR20+CO21-CP21) -> 126
H22: =SUM(H21+E22-F22) -> 147 | P22: =SUM(P21+M22-N22) -> 147 | U22: 0 | X22: =SUM(X21+U22-V22) -> 146 | AC22: 0 | AF22: =SUM(AF21+AC22-AD22) -> 144 | AN22: =SUM(AN21+AK22-AL22) -> 142 | AV22: =SUM(AV21+AS22-AT22) -> 142 | BD22: =SUM(BD21+BA22-BB22) -> 140 | BF22: 45793 | BI22: 0 | BJ22: 1 | BK22: DAA | BL22: =SUM(BL21+BI22-BJ22) -> 137 | BQ22: 0 | BT22: =SUM(BT21+BQ22-BR22) -> 137 | CB22: =SUM(CB21+BY22-BZ22) -> 134 | CJ22: =SUM(CJ21+CG22-CH22) -> 129 | CL22: 45908 | CO22: 0 | CP22: 12 | CQ22: DCB | CR22: =SUM(CR21+CO22-CP22) -> 114
H23: =SUM(H22+E23-F23) -> 147 | P23: =SUM(P22+M23-N23) -> 147 | X23: =SUM(X22+U24-V24) -> 146 | AC23: 0 | AF23: =SUM(AF22+AC24-AD24) -> 144 | AN23: =SUM(AN22+AK24-AL24) -> 142 | AV23: =SUM(AV22+AS24-AT24) -> 142 | BD23: =SUM(BD22+BA24-BB24) -> 140 | BL23: =SUM(BL22+BI24-BJ24) -> 137 | BT23: =SUM(BT22+BQ24-BR24) -> 137 | CB23: =SUM(CB22+BY24-BZ24) -> 134 | CJ23: =SUM(CJ22+CG23-CH23) -> 129 | CL23: 45915 | CO23: 0 | CP23: 1 | CQ23: DCB | CR23: =SUM(CR22+CO24-CP24) -> 114
H24: =SUM(H23+E24-F24) -> 147 | P24: =SUM(P23+M25-N25) -> 147 | AF24: =SUM(AF23+AC25-AD25) -> 144 | AN24: =SUM(AN23+AK25-AL25) -> 142 | AV24: =SUM(AV23+AS25-AT25) -> 142 | BD24: =SUM(BD23+BA25-BB25) -> 140 | BL24: =SUM(BL23+BI25-BJ25) -> 137 | BT24: =SUM(BT23+BQ25-BR25) -> 137 | CB24: =SUM(CB23+BY25-BZ25) -> 134 | CJ24: =SUM(CJ23+CG24-CH24) -> 129 | CR24: =SUM(CR23+CO25-CP25) -> 114
H25: =SUM(H24+E25-F25) -> 147 | P25: =SUM(P24+M26-N26) -> 147 | AF25: =SUM(AF24+AC26-AD26) -> 144 | AN25: =SUM(AN24+AK26-AL26) -> 142 | AV25: =SUM(AV21+AS25-AT25) -> 142 | BD25: =SUM(BD24+BA26-BB26) -> 140 | BL25: =SUM(BL24+BI26-BJ26) -> 137 | BT25: =SUM(BT24+BQ25-BR25) -> 137 | CB25: =SUM(CB24+BY26-BZ26) -> 134 | CJ25: =SUM(CJ21+CG25-CH25) -> 129 | CR25: =SUM(CR24+CO26-CP26) -> 114
B26: Agrafeuses | J26: Agrafeuses | R26: Agrafeuses | Z26: Agrafeuses | AH26: Agrafeuses | AP26: Agrafeuses | AX26: Agrafeuses | BF26: Agrafeuses | BN26: Agrafeuses | BV26: Agrafeuses | CD26: Agrafeuses | CL26: Agrafeuses
E27: Rentree | F27: Sortie | G27: Direction | H27: Stock | M27: Rentree | N27: Sortie | O27: Direction | P27: Stock | U27: Rentree | V27: Sortie | W27: Direction | X27: Stock | AC27: Rentree | AD27: Sortie | AE27: Direction | AF27: Stock | AK27: Rentree | AL27: Sortie | AM27: Direction | AN27: Stock | AS27: Rentree | AT27: Sortie | AU27: Direction | AV27: Stock | BA27: Rentree | BB27: Sortie | BC27: Direction | BD27: Stock | BI27: Rentree | BJ27: Sortie | BK27: Direction | BL27: Stock | BQ27: Rentree | BR27: Sortie | BS27: Direction | BT27: Stock | BY27: Rentree | BZ27: Sortie | CA27: Direction | CB27: Stock | CG27: Rentree | CH27: Sortie | CI27: Direction | CJ27: Stock | CO27: Rentree | CP27: Sortie | CQ27: Direction | CR27: Stock
B28: Stock 30 Sept.24 | E28: Unité | F28: Unités | J28: Stock 31 Oct. 24 | M28: Unités | N28: Unités | P28: 0 | R28: Stock 30 Nov. 24 | U28: Unités | V28: Unités | X28: 0 | Z28: Stock 31 Déc. 24 | AC28: Unités | AD28: Unités | AF28: 0 | AH28: Stock 31 Jan. 25 | AK28: Unités | AL28: Unités | AN28: 24 | AP28: Stock 28 Fév. 25 | AS28: Unités | AT28: Unités | AV28: 17 | AX28: Stock 31 Mars. 25 | BA28: Unités | BB28: Unités | BD28: 17 | BF28: Stock 30 Avril. 25 | BI28: Unités | BJ28: Unités | BL28: 16 | BN28: Stock 31 Mai. 25 | BQ28: Unités | BR28: Unités | BT28: 12 | BV28: Stock 30 Juin. 25 | BY28: Unités | BZ28: Unités | CB28: 12 | CD28: Stock 31 Juil. 25 | CG28: Unités | CH28: Unités | CJ28: =CB28 -> 12 | CL28: Stock 31 Août. 24 | CO28: Unités | CP28: Unités | CR28: =CJ29 -> 12
E29: 0 | M29: 0 | P29: =SUM(P28+M29-N29) -> 0 | X29: =SUM(X28+U29-V29) -> 0 | Z29: 45686 | AC29: 24 | AD29: 0 | AE29: DAA | AF29: =SUM(AF28+AC29-AD29) -> 24 | AH29: 45691 | AK29: 0 | AL29: 2 | AM29: DCB | AN29: =SUM(AN28+AK29-AL29) -> 22 | AP29: 45799 | AS29: 0 | AT29: 2 | AU29: DEPB | AV29: =SUM(AV28+AS29-AT29) -> 15 | AX29: 45762 | BA29: 0 | BB29: 1 | BC29: DSI | BD29: =SUM(BD28+BA29-BB29) -> 16 | BF29: 45793 | BI29: 0 | BJ29: 2 | BK29: DAA | BL29: =SUM(BL28+BI29-BJ29) -> 14 | BT29: =SUM(BT28+BQ29-BR29) -> 12 | CB29: 12 | CG29: 0 | CJ29: =SUM(CJ28+CG29-CH29) -> 12 | CR29: =SUM(CR28+CO29-CP29) -> 12
P30: =SUM(P29+M30-N30) -> 0 | X30: =SUM(X29+U30-V30) -> 0 | AC30: 0 | AF30: =SUM(AF29+AC30-AD30) -> 24 | AH30: 45698 | AK30: 0 | AL30: 2 | AM30: DASIP | AN30: =SUM(AN29+AK30-AL30) -> 20 | AS30: 0 | AV30: =SUM(AV29+AS30-AT30) -> 15 | BD30: =SUM(BD29+BA30-BB30) -> 16 | BF30: 45799 | BI30: 0 | BJ30: 2 | BK30: DEPB | BL30: =SUM(BL29+BI30-BJ30) -> 12 | BT30: =SUM(BT29+BQ30-BR30) -> 12 | CB30: =SUM(CB29+BY30-BZ30) -> 12 | CG30: 0 | CJ30: =SUM(CJ29+CG30-CH30) -> 12 | CR30: =SUM(CR29+CO30-CP30) -> 12
P31: =SUM(P30+M31-N31) -> 0 | X31: =SUM(X30+U31-V31) -> 0 | AF31: =SUM(AF30+AC31-AD31) -> 24 | AH31: 45702 | AK31: 0 | AL31: 1 | AM31: DGA | AN31: =SUM(AN30+AK31-AL31) -> 19 | AV31: =SUM(AV30+AS31-AT31) -> 15 | BD31: =SUM(BD30+BA31-BB31) -> 16 | BL31: =SUM(BL30+BI31-BJ31) -> 12 | BT31: =SUM(BT30+BQ31-BR31) -> 12 | CB31: =SUM(CB30+BY31-BZ31) -> 12 | CG31: 0 | CJ31: =SUM(CJ30+CG31-CH31) -> 12 | CR31: =SUM(CR30+CO31-CP31) -> 12
P32: =SUM(P31+M32-N32) -> 0 | X32: =SUM(X31+U32-V32) -> 0 | AF32: =SUM(AF31+AC32-AD32) -> 24 | AH32: 45705 | AK32: 0 | AL32: 1 | AM32: DCB | AN32: =SUM(AN31+AK32-AL32) -> 18 | AV32: =SUM(AV31+AS32-AT32) -> 15 | BD32: =SUM(BD31+BA32-BB32) -> 16 | BL32: =SUM(BL31+BI32-BJ32) -> 12 | BT32: =SUM(BT31+BQ32-BR32) -> 12 | CB32: =SUM(CB31+BY32-BZ32) -> 12 | CG32: 0 | CJ32: =SUM(CJ31+CG32-CH32) -> 12 | CR32: =SUM(CR31+CO32-CP32) -> 12
P33: =SUM(P32+M33-N33) -> 0 | X33: =SUM(X32+U33-V33) -> 0 | AF33: =SUM(AF32+AC33-AD33) -> 24 | AH33: 45714 | AK33: 0 | AL33: 1 | AM33: DS | AN33: =SUM(AN32+AK33-AL33) -> 17 | AV33: =SUM(AV32+AS33-AT33) -> 15 | BD33: =SUM(BD32+BA33-BB33) -> 16 | BL33: =SUM(BL32+BI33-BJ33) -> 12 | BT33: =SUM(BT32+BQ33-BR33) -> 12 | CB33: =SUM(CB32+BY33-BZ33) -> 12 | CJ33: =SUM(CJ32+CG33-CH33) -> 12 | CR33: =SUM(CR32+CO33-CP33) -> 12
P34: =SUM(P33+M34-N34) -> 0 | X34: =SUM(X33+U34-V34) -> 0 | AF34: =SUM(AF33+AC34-AD34) -> 24 | AN34: =SUM(AN33+AK34-AL34) -> 17 | AV34: =SUM(AV33+AS34-AT34) -> 15 | BD34: =SUM(BD33+BA34-BB34) -> 16 | BL34: =SUM(BL33+BI34-BJ34) -> 12 | BT34: =SUM(BT33+BQ34-BR34) -> 12 | CB34: =SUM(CB33+BY34-BZ34) -> 12 | CJ34: =SUM(CJ33+CG34-CH34) -> 12 | CR34: =SUM(CR33+CO34-CP34) -> 12
P35: =SUM(P34+M35-N35) -> 0 | X35: =SUM(X34+U35-V35) -> 0 | AF35: =SUM(AF34+AC35-AD35) -> 24 | AN35: =SUM(AN34+AK35-AL35) -> 17 | AV35: =SUM(AV34+AS35-AT35) -> 15 | BD35: =SUM(BD34+BA35-BB35) -> 16 | BL35: =SUM(BL34+BI35-BJ35) -> 12 | BT35: =SUM(BT34+BQ35-BR35) -> 12 | CB35: =SUM(CB34+BY35-BZ35) -> 12 | CJ35: =SUM(CJ34+CG35-CH35) -> 12 | CR35: =SUM(CR34+CO35-CP35) -> 12
P36: =SUM(P35+M36-N36) -> 0 | X36: =SUM(X35+U36-V36) -> 0 | AF36: =SUM(AF35+AC36-AD36) -> 24 | AN36: =SUM(AN35+AK36-AL36) -> 17 | AV36: =SUM(AV35+AS36-AT36) -> 15 | BD36: =SUM(BD35+BA36-BB36) -> 16 | BL36: =SUM(BL35+BI36-BJ36) -> 12 | BT36: =SUM(BT35+BQ36-BR36) -> 12 | CB36: =SUM(CB35+BY36-BZ36) -> 12 | CJ36: =SUM(CJ35+CG36-CH36) -> 12 | CR36: =SUM(CR35+CO36-CP36) -> 12
P37: =SUM(P36+M37-N37) -> 0 | X37: =SUM(X36+U37-V37) -> 0 | AF37: =SUM(AF36+AC37-AD37) -> 24 | AN37: =SUM(AN36+AK37-AL37) -> 17 | AV37: =SUM(AV36+AS37-AT37) -> 15 | BD37: =SUM(BD36+BA37-BB37) -> 16 | BL37: =SUM(BL36+BI37-BJ37) -> 12 | BT37: =SUM(BT36+BQ37-BR37) -> 12 | CB37: =SUM(CB36+BY37-BZ37) -> 12 | CJ37: =SUM(CJ36+CG37-CH37) -> 12 | CR37: =SUM(CR36+CO37-CP37) -> 12
P38: =SUM(P37+M38-N38) -> 0 | X38: =SUM(X37+U38-V38) -> 0 | AF38: =SUM(AF37+AC38-AD38) -> 24 | AN38: =SUM(AN37+AK38-AL38) -> 17 | AV38: =SUM(AV37+AS38-AT38) -> 15 | BD38: =SUM(BD37+BA38-BB38) -> 16 | BL38: =SUM(BL37+BI38-BJ38) -> 12 | BT38: =SUM(BT37+BQ38-BR38) -> 12 | CB38: =SUM(CB37+BY38-BZ38) -> 12 | CJ38: =SUM(CJ37+CG38-CH38) -> 12 | CR38: =SUM(CR37+CO38-CP38) -> 12
P39: =SUM(P38+M39-N39) -> 0 | X39: =SUM(X38+U39-V39) -> 0 | AF39: =SUM(AF38+AC39-AD39) -> 24 | AN39: =SUM(AN38+AK39-AL39) -> 17 | AV39: =SUM(AV38+AS39-AT39) -> 15 | BD39: =SUM(BD38+BA39-BB39) -> 16 | BL39: =SUM(BL38+BI39-BJ39) -> 12 | BT39: =SUM(BT38+BQ39-BR39) -> 12 | CB39: =SUM(CB38+BY39-BZ39) -> 12 | CJ39: =SUM(CJ38+CG39-CH39) -> 12 | CR39: =SUM(CR38+CO39-CP39) -> 12
B40: Aiguisoirs électriques | J40: Aiguisoirs électriques | R40: Aiguisoirs électriques | Z40: Aiguisoirs électriques | AH40: Aiguisoirs électriques | AP40: Aiguisoirs électriques | AX40: Aiguisoirs électriques | BF40: Aiguisoirs électriques | BN40: Aiguisoirs électriques | BV40: Aiguisoirs électriques | CD40: Aiguisoirs électriques | CL40: Aiguisoirs électriques
E41: Rentree | F41: Sortie | G41: Direction | H41: Stock | M41: Rentree | N41: Sortie | O41: Direction | P41: Stock | U41: Rentree | V41: Sortie | W41: Direction | X41: Stock | AC41: Rentree | AD41: Sortie | AE41: Direction | AF41: Stock | AK41: Rentree | AL41: Sortie | AM41: Direction | AN41: Stock | AS41: Rentree | AT41: Sortie | AU41: Direction | AV41: Stock | BA41: Rentree | BB41: Sortie | BC41: Direction | BD41: Stock | BI41: Rentree | BJ41: Sortie | BK41: Direction | BL41: Stock | BQ41: Rentree | BR41: Sortie | BS41: Direction | BT41: Stock | BY41: Rentree | BZ41: Sortie | CA41: Direction | CB41: Stock | CG41: Rentree | CH41: Sortie | CI41: Direction | CJ41: Stock | CO41: Rentree | CP41: Sortie | CQ41: Direction | CR41: Stock
B42: Stock 30 Sept.24 | E42: Unités | F42: Unités | H42: 11 | J42: Stock 31 Oct. 24 | M42: Unités | N42: Unités | P42: 11 | R42: Stock 30 Nov. 24 | U42: Unités | V42: Unités | X42: 10 | Z42: Stock 31 Déc. 24 | AC42: Unités | AD42: Unités | AF42: 7 | AH42: Stock 31 Jan. 25 | AK42: Unités | AL42: Unités | AN42: 7 | AP42: Stock 28 Fév. 25 | AS42: Unités | AT42: Unités | AV42: 6 | AX42: Stock 31 Mars. 25 | BA42: Unités | BB42: Unités | BD42: 6 | BF42: Stock 30 Avril. 25 | BI42: Unités | BJ42: Unités | BL42: 6 | BN42: Stock 31 Mai. 25 | BQ42: Unités | BR42: Unités | BT42: 6 | BV42: Stock 30 Juin. 25 | BY42: Unités | BZ42: Unités | CB42: 6 | CD42: Stock 31 Juil. 25 | CG42: Unités | CH42: Unités | CJ42: =CB43 -> 6 | CL42: Stock 31 Août. 24 | CO42: Unités | CP42: Unités | CR42: =CJ43 -> 6
H43: =SUM(H42+E43-F43) -> 11 | J43: 45609 | M43: 0 | N43: 1 | O43: DG | P43: =SUM(P42+M43-N43) -> 10 | R43: 45635 | U43: 0 | V43: 1 | W43: DRH | X43: =SUM(X42+U43-V43) -> 9 | AF43: =SUM(AF42+AC43-AD43) -> 7 | AH43: 45702 | AK43: 0 | AL43: 1 | AM43: DGA | AN43: =SUM(AN42+AK43-AL43) -> 6 | AV43: =SUM(AV42+AS43-AT43) -> 6 | BD43: =SUM(BD42+BA43-BB43) -> 6 | BL43: =SUM(BL42+BI43-BJ43) -> 6 | BT43: 6 | CB43: =SUM(CB42+BY43-BZ43) -> 6 | CJ43: =SUM(CJ42+CG43-CH43) -> 6 | CR43: =SUM(CR42+CO43-CP43) -> 6
H44: =SUM(H43+E44-F44) -> 11 | P44: =SUM(P43+M44-N44) -> 10 | R44: 45638 | U44: 0 | V44: 2 | X44: =SUM(X43+U44-V44) -> 7 | AF44: =SUM(AF43+AC44-AD44) -> 7 | AN44: =SUM(AN43+AK44-AL44) -> 6 | AV44: =SUM(AV43+AS44-AT44) -> 6 | BD44: =SUM(BD43+BA44-BB44) -> 6 | BL44: =SUM(BL43+BI44-BJ44) -> 6 | BT44: 6 | CB44: =SUM(CB43+BY44-BZ44) -> 6 | CJ44: =SUM(CJ43+CG44-CH44) -> 6 | CR44: =SUM(CR43+CO44-CP44) -> 6
...

Sheet R
B18: Fournitures de bureau

Sheet T
B2: Direction Générale du Budget | J2: Direction Générale du Budget | R2: Direction Générale du Budget | Z2: Direction Générale du Budget | AH2: Direction Générale du Budget | AP2: Direction Générale du Budget | AX2: Direction Générale du Budget | BF2: Direction Générale du Budget | BN2: Direction Générale du Budget | BV2: Direction Générale du Budget | CD2: Direction Générale du Budget | CL2: Direction Générale du Budget
B3: Inventaire stocks fournitures | J3: Inventaire stocks fournitures | R3: Inventaire stocks fournitures | Z3: Inventaire stocks fournitures | AH3: Inventaire stocks fournitures | AP3: Inventaire stocks fournitures | AX3: Inventaire stocks fournitures | BF3: Inventaire stocks fournitures | BN3: Inventaire stocks fournitures | BV3: Inventaire stocks fournitures | CD3: Inventaire stocks fournitures | CL3: Inventaire stocks fournitures
B4: Exercice: 2022-2023 | J4: Exercice: 2022-2023 | R4: Exercice: 2022-2023 | Z4: Exercice: 2022-2023 | AH4: Exercice: 2022-2023 | AP4: Exercice: 2022-2023 | AX4: Exercice: 2022-2023 | BF4: Exercice: 2022-2023 | BN4: Exercice: 2022-2023 | BV4: Exercice: 2022-2023 | CD4: Exercice: 2022-2023 | CL4: Exercice: 2022-2023
B6: 44835 | J6: 44866 | R6: 44896 | Z6: 44562 | AH6: 44958 | AP6: 44986 | AX6: 45017 | BF6: 45047 | BN6: 45078 | BV6: 45108 | CD6: 45139 | CL6: 45170
B7: Produits ménagers | J7: Produits ménagers | R7: Produits ménagers | Z7: Produits ménagers | AH7: Produits ménagers | AP7: Produits ménagers | AX7: Produits ménagers | BF7: Produits ménagers | BN7: Produits ménagers | BV7: Produits ménagers | CD7: Produits ménagers | CL7: Produits ménagers
B9: Tasses simples | J9: Tasses simples | R9: Tasses simples | Z9: Tasses simples | AH9: Tasses simples | AP9: Tasses simples | AX9: Tasses simples | BF9: Tasses simples | BN9: Tasses simples | BV9: Tasses simples | CD9: Tasses simples | CL9: Tasses simples
E10: Rentree | F10: Sortie | G10: Direction | H10: Balance | M10: Rentree | N10: Sortie | O10: Direction | P10: Balance | U10: Rentree | V10: Sortie | W10: Direction | X10: Balance | AC10: Rentree | AD10: Sortie | AE10: Direction | AF10: Balance | AK10: Rentree | AL10: Sortie | AM10: Direction | AN10: Balance | AS10: Rentree | AT10: Sortie | AU10: Direction | AV10: Balance | BA10: Rentree | BB10: Sortie | BC10: Direction | BD10: Balance | BI10: Rentree | BJ10: Sortie | BK10: Direction | BL10: Balance | BQ10: Rentree | BR10: Sortie | BS10: Direction | BT10: Balance | BY10: Rentree | BZ10: Sortie | CA10: Direction | CB10: Balance | CG10: Rentree | CH10: Sortie | CI10: Direction | CJ10: Balance | CO10: Rentree | CP10: Sortie | CQ10: Direction | CR10: Balance
B11: Balance 30 Sept.22 | E11: Unités | F11: Unités | H11: 10 | J11: Balance 31 Oct. 22 | M11: Unités | N11: Unités | P11: 10 | R11: Balance 30 Nov. 22 | U11: Unités | V11: Unités | X11: 10 | Z11: Balance 31 Déc. 22 | AC11: Unités | AD11: Unités | AF11: 10 | AH11: Balance 31 Jan. 23 | AK11: Unités | AL11: Unités | AN11: 10 | AP11: Balance 28 Fév. 23 | AS11: Unités | AT11: Unités | AV11: 10 | AX11: Balance 31 Mars. 23 | BA11: Unités | BB11: Unités | BD11: 10 | BF11: Balance 30 Avril. 23 | BI11: Unités | BJ11: Unités | BL11: 10 | BN11: Balance 31 Mai. 23 | BQ11: Unités | BR11: Unités | BT11: 10 | BV11: Balance 30 Juin. 23 | BY11: Unités | BZ11: Unités | CB11: 10 | CD11: Balance 31 Juil. 23 | CG11: Unités | CH11: Unités | CJ11: 10 | CL11: Balance 31 Août. 23 | CO11: Unités | CP11: Unités | CR11: 10
H12: =SUM(H11+E12-F12) -> 10 | P12: =SUM(P11+M12-N12) -> 10 | X12: =SUM(X11+U12-V12) -> 10 | AF12: =SUM(AF11+AC12-AD12) -> 10 | AN12: =SUM(AN11+AK12-AL12) -> 10 | AV12: =SUM(AV11+AS12-AT12) -> 10 | BD12: =SUM(BD11+BA12-BB12) -> 10 | BL12: =SUM(BL11+BI12-BJ12) -> 10 | BT12: =SUM(BT11+BQ12-BR12) -> 10 | CB12: =SUM(CB11+BY12-BZ12) -> 10 | CJ12: =SUM(CJ11+CG12-CH12) -> 10 | CR12: =SUM(CR11+CO12-CP12) -> 10
H13: =SUM(H12+E13-F13) -> 10 | P13: =SUM(P12+M13-N13) -> 10 | X13: =SUM(X12+U13-V13) -> 10 | AF13: =SUM(AF12+AC13-AD13) -> 10 | AN13: =SUM(AN12+AK13-AL13) -> 10 | AV13: =SUM(AV12+AS13-AT13) -> 10 | BD13: =SUM(BD12+BA13-BB13) -> 10 | BL13: =SUM(BL12+BI13-BJ13) -> 10 | BT13: =SUM(BT12+BQ13-BR13) -> 10 | CB13: =SUM(CB12+BY13-BZ13) -> 10 | CJ13: =SUM(CJ12+CG13-CH13) -> 10 | CR13: =SUM(CR12+CO13-CP13) -> 10
H14: =SUM(H13+E14-F14) -> 10 | P14: =SUM(P13+M14-N14) -> 10 | X14: =SUM(X13+U14-V14) -> 10 | AF14: =SUM(AF13+AC14-AD14) -> 10 | AN14: =SUM(AN13+AK14-AL14) -> 10 | AV14: =SUM(AV13+AS14-AT14) -> 10 | BD14: =SUM(BD13+BA14-BB14) -> 10 | BL14: =SUM(BL13+BI14-BJ14) -> 10 | BT14: =SUM(BT13+BQ14-BR14) -> 10 | CB14: =SUM(CB13+BY14-BZ14) -> 10 | CJ14: =SUM(CJ13+CG14-CH14) -> 10 | CR14: =SUM(CR13+CO14-CP14) -> 10
H15: =SUM(H14+E15-F15) -> 10 | P15: =SUM(P14+M15-N15) -> 10 | X15: =SUM(X14+U15-V15) -> 10 | AF15: =SUM(AF14+AC15-AD15) -> 10 | AN15: =SUM(AN14+AK15-AL15) -> 10 | AV15: =SUM(AV14+AS15-AT15) -> 10 | BD15: =SUM(BD14+BA15-BB15) -> 10 | BL15: =SUM(BL14+BI15-BJ15) -> 10 | BT15: =SUM(BT14+BQ15-BR15) -> 10 | CB15: =SUM(CB14+BY15-BZ15) -> 10 | CJ15: =SUM(CJ14+CG15-CH15) -> 10 | CR15: =SUM(CR14+CO15-CP15) -> 10
H16: =SUM(H15+E16-F16) -> 10 | P16: =SUM(P15+M16-N16) -> 10 | X16: =SUM(X15+U16-V16) -> 10 | AF16: =SUM(AF15+AC16-AD16) -> 10 | AN16: =SUM(AN15+AK16-AL16) -> 10 | AV16: =SUM(AV15+AS16-AT16) -> 10 | BD16: =SUM(BD15+BA16-BB16) -> 10 | BL16: =SUM(BL15+BI16-BJ16) -> 10 | BT16: =SUM(BT15+BQ16-BR16) -> 10 | CB16: =SUM(CB15+BY16-BZ16) -> 10 | CJ16: =SUM(CJ15+CG16-CH16) -> 10 | CR16: =SUM(CR15+CO16-CP16) -> 10
H17: =SUM(H16+E17-F17) -> 10 | P17: =SUM(P16+M17-N17) -> 10 | X17: =SUM(X16+U17-V17) -> 10 | AF17: =SUM(AF16+AC17-AD17) -> 10 | AN17: =SUM(AN16+AK17-AL17) -> 10 | AV17: =SUM(AV16+AS17-AT17) -> 10 | BD17: =SUM(BD16+BA17-BB17) -> 10 | BL17: =SUM(BL16+BI17-BJ17) -> 10 | BT17: =SUM(BT16+BQ17-BR17) -> 10 | CB17: =SUM(CB16+BY17-BZ17) -> 10 | CJ17: =SUM(CJ16+CG17-CH17) -> 10 | CR17: =SUM(CR16+CO17-CP17) -> 10
B18: Tasses à café | J18: Tasses à café | R18: Tasses à café | Z18: Tasses à café | AH18: Tasses à café | AP18: Tasses à café | AX18: Tasses à café | BF18: Tasses à café | BN18: Tasses à café | BV18: Tasses à café | CD18: Tasses à café | CL18: Tasses à café
E19: Rentree | F19: Sortie | G19: Direction | H19: Balance | M19: Rentree | N19: Sortie | O19: Direction | P19: Balance | U19: Rentree | V19: Sortie | W19: Direction | X19: Balance | AC19: Rentree | AD19: Sortie | AE19: Direction | AF19: Balance | AK19: Rentree | AL19: Sortie | AM19: Direction | AN19: Balance | AS19: Rentree | AT19: Sortie | AU19: Direction | AV19: Balance | BA19: Rentree | BB19: Sortie | BC19: Direction | BD19: Balance | BI19: Rentree | BJ19: Sortie | BK19: Direction | BL19: Balance | BQ19: Rentree | BR19: Sortie | BS19: Direction | BT19: Balance | BY19: Rentree | BZ19: Sortie | CA19: Direction | CB19: Balance | CG19: Rentree | CH19: Sortie | CI19: Direction | CJ19: Balance | CO19: Rentree | CP19: Sortie | CQ19: Direction | CR19: Balance
B20: Balance 30 Sept.22 | E20: Unités | F20: Unités | H20: 12 | J20: Balance 31 Oct. 22 | M20: Unités | N20: Unités | P20: 12 | R20: Balance 30 Nov. 22 | U20: Unités | V20: Unités | X20: 12 | Z20: Balance 31 Déc. 22 | AC20: Unités | AD20: Unités | AF20: 12 | AH20: Balance 31 Jan. 23 | AK20: Unités | AL20: Unités | AN20: 12 | AP20: Balance 28 Fév. 23 | AS20: Unités | AT20: Unités | AV20: 12 | AX20: Balance 31 Mars. 23 | BA20: Unités | BB20: Unités | BD20: 12 | BF20: Balance 30 Avril. 23 | BI20: Unités | BJ20: Unités | BL20: 12 | BN20: Balance 31 Mai. 23 | BQ20: Unités | BR20: Unités | BT20: 12 | BV20: Balance 30 Juin. 23 | BY20: Unités | BZ20: Unités | CB20: 12 | CD20: Balance 31 Juil. 23 | CG20: Unités | CH20: Unités | CJ20: 12 | CL20: Balance 31 Août. 23 | CO20: Unités | CP20: Unités | CR20: 12
H21: =SUM(H20+E21-F21) -> 12 | P21: =SUM(P20+M21-N21) -> 12 | X21: =SUM(X20+U21-V21) -> 12 | AF21: =SUM(AF20+AC21-AD21) -> 12 | AN21: =SUM(AN20+AK21-AL21) -> 12 | AV21: =SUM(AV20+AS21-AT21) -> 12 | BD21: =SUM(BD20+BA21-BB21) -> 12 | BL21: =SUM(BL20+BI21-BJ21) -> 12 | BT21: =SUM(BT20+BQ21-BR21) -> 12 | CB21: =SUM(CB20+BY21-BZ21) -> 12 | CJ21: =SUM(CJ20+CG21-CH21) -> 12 | CR21: =SUM(CR20+CO21-CP21) -> 12
H22: =SUM(H21+E22-F22) -> 12 | P22: =SUM(P21+M22-N22) -> 12 | X22: =SUM(X21+U22-V22) -> 12 | AF22: =SUM(AF21+AC22-AD22) -> 12 | AN22: =SUM(AN21+AK22-AL22) -> 12 | AV22: =SUM(AV21+AS22-AT22) -> 12 | BD22: =SUM(BD21+BA22-BB22) -> 12 | BL22: =SUM(BL21+BI22-BJ22) -> 12 | BT22: =SUM(BT21+BQ22-BR22) -> 12 | CB22: =SUM(CB21+BY22-BZ22) -> 12 | CJ22: =SUM(CJ21+CG22-CH22) -> 12 | CR22: =SUM(CR21+CO22-CP22) -> 12
H23: =SUM(H22+E23-F23) -> 12 | P23: =SUM(P22+M23-N23) -> 12 | X23: =SUM(X22+U23-V23) -> 12 | AF23: =SUM(AF22+AC23-AD23) -> 12 | AN23: =SUM(AN22+AK23-AL23) -> 12 | AV23: =SUM(AV22+AS23-AT23) -> 12 | BD23: =SUM(BD22+BA23-BB23) -> 12 | BL23: =SUM(BL22+BI23-BJ23) -> 12 | BT23: =SUM(BT22+BQ23-BR23) -> 12 | CB23: =SUM(CB22+BY23-BZ23) -> 12 | CJ23: =SUM(CJ22+CG23-CH23) -> 12 | CR23: =SUM(CR22+CO23-CP23) -> 12
H24: =SUM(H23+E24-F24) -> 12 | P24: =SUM(P23+M24-N24) -> 12 | X24: =SUM(X23+U24-V24) -> 12 | AF24: =SUM(AF23+AC24-AD24) -> 12 | AN24: =SUM(AN23+AK24-AL24) -> 12 | AV24: =SUM(AV23+AS24-AT24) -> 12 | BD24: =SUM(BD23+BA24-BB24) -> 12 | BL24: =SUM(BL23+BI24-BJ24) -> 12 | BT24: =SUM(BT23+BQ24-BR24) -> 12 | CB24: =SUM(CB23+BY24-BZ24) -> 12 | CJ24: =SUM(CJ23+CG24-CH24) -> 12 | CR24: =SUM(CR23+CO24-CP24) -> 12
H25: =SUM(H24+E25-F25) -> 12 | P25: =SUM(P24+M25-N25) -> 12 | X25: =SUM(X24+U25-V25) -> 12 | AF25: =SUM(AF24+AC25-AD25) -> 12 | AN25: =SUM(AN24+AK25-AL25) -> 12 | AV25: =SUM(AV24+AS25-AT25) -> 12 | BD25: =SUM(BD24+BA25-BB25) -> 12 | BL25: =SUM(BL24+BI25-BJ25) -> 12 | BT25: =SUM(BT24+BQ25-BR25) -> 12 | CB25: =SUM(CB24+BY25-BZ25) -> 12 | CJ25: =SUM(CJ24+CG25-CH25) -> 12 | CR25: =SUM(CR24+CO25-CP25) -> 12
H26: =SUM(H25+E26-F26) -> 12 | P26: =SUM(P25+M26-N26) -> 12 | X26: =SUM(X25+U26-V26) -> 12 | AF26: =SUM(AF25+AC26-AD26) -> 12 | AN26: =SUM(AN25+AK26-AL26) -> 12 | AV26: =SUM(AV25+AS26-AT26) -> 12 | BD26: =SUM(BD25+BA26-BB26) -> 12 | BL26: =SUM(BL25+BI26-BJ26) -> 12 | BT26: =SUM(BT25+BQ26-BR26) -> 12 | CB26: =SUM(CB25+BY26-BZ26) -> 12 | CJ26: =SUM(CJ25+CG26-CH26) -> 12 | CR26: =SUM(CR25+CO26-CP26) -> 12
B27: Tasses à thé | J27: Tasses à thé | R27: Tasses à thé | Z27: Tasses à thé | AH27: Tasses à thé | AP27: Tasses à thé | AX27: Tasses à thé | BF27: Tasses à thé | BN27: Tasses à thé | BV27: Tasses à thé | CD27: Tasses à thé | CL27: Tasses à thé
E28: Rentree | F28: Sortie | G28: Direction | H28: Balance | M28: Rentree | N28: Sortie | O28: Direction | P28: Balance | U28: Rentree | V28: Sortie | W28: Direction | X28: Balance | AC28: Rentree | AD28: Sortie | AE28: Direction | AF28: Balance | AK28: Rentree | AL28: Sortie | AM28: Direction | AN28: Balance | AS28: Rentree | AT28: Sortie | AU28: Direction | AV28: Balance | BA28: Rentree | BB28: Sortie | BC28: Direction | BD28: Balance | BI28: Rentree | BJ28: Sortie | BK28: Direction | BL28: Balance | BQ28: Rentree | BR28: Sortie | BS28: Direction | BT28: Balance | BY28: Rentree | BZ28: Sortie | CA28: Direction | CB28: Balance | CG28: Rentree | CH28: Sortie | CI28: Direction | CJ28: Balance | CO28: Rentree | CP28: Sortie | CQ28: Direction | CR28: Balance
B29: Balance 30 Sept.22 | E29: Unités | F29: Unités | H29: 12 | J29: Balance 31 Oct. 22 | M29: Unités | N29: Unités | P29: 12 | R29: Balance 30 Nov. 22 | U29: Unités | V29: Unités | X29: 12 | Z29: Balance 31 Déc. 22 | AC29: Unités | AD29: Unités | AF29: 12 | AH29: Balance 31 Jan. 23 | AK29: Unités | AL29: Unités | AN29: 12 | AP29: Balance 28 Fév. 23 | AS29: Unités | AT29: Unités | AV29: 12 | AX29: Balance 31 Mars. 23 | BA29: Unités | BB29: Unités | BD29: 12 | BF29: Balance 30 Avril. 23 | BI29: Unités | BJ29: Unités | BL29: 12 | BN29: Balance 31 Mai. 23 | BQ29: Unités | BR29: Unités | BT29: 12 | BV29: Balance 30 Juin. 23 | BY29: Unités | BZ29: Unités | CB29: 12 | CD29: Balance 31 Juil. 23 | CG29: Unités | CH29: Unités | CJ29: 12 | CL29: Balance 31 Août. 23 | CO29: Unités | CP29: Unités | CR29: 12
H30: =SUM(H29+E30-F30) -> 12 | P30: =SUM(P29+M30-N30) -> 12 | X30: =SUM(X29+U30-V30) -> 12 | AF30: =SUM(AF29+AC30-AD30) -> 12 | AN30: =SUM(AN29+AK30-AL30) -> 12 | AV30: =SUM(AV29+AS30-AT30) -> 12 | BD30: =SUM(BD29+BA30-BB30) -> 12 | BL30: =SUM(BL29+BI30-BJ30) -> 12 | BT30: =SUM(BT29+BQ30-BR30) -> 12 | CB30: =SUM(CB29+BY30-BZ30) -> 12 | CJ30: =SUM(CJ29+CG30-CH30) -> 12 | CR30: =SUM(CR29+CO30-CP30) -> 12
H31: =SUM(H30+E31-F31) -> 12 | P31: =SUM(P30+M31-N31) -> 12 | X31: =SUM(X30+U31-V31) -> 12 | AF31: =SUM(AF30+AC31-AD31) -> 12 | AN31: =SUM(AN30+AK31-AL31) -> 12 | AV31: =SUM(AV30+AS31-AT31) -> 12 | BD31: =SUM(BD30+BA31-BB31) -> 12 | BL31: =SUM(BL30+BI31-BJ31) -> 12 | BT31: =SUM(BT30+BQ31-BR31) -> 12 | CB31: =SUM(CB30+BY31-BZ31) -> 12 | CJ31: =SUM(CJ30+CG31-CH31) -> 12 | CR31: =SUM(CR30+CO31-CP31) -> 12
H32: =SUM(H31+E32-F32) -> 12 | P32: =SUM(P31+M32-N32) -> 12 | X32: =SUM(X31+U32-V32) -> 12 | AF32: =SUM(AF31+AC32-AD32) -> 12 | AN32: =SUM(AN31+AK32-AL32) -> 12 | AV32: =SUM(AV31+AS32-AT32) -> 12 | BD32: =SUM(BD31+BA32-BB32) -> 12 | BL32: =SUM(BL31+BI32-BJ32) -> 12 | BT32: =SUM(BT31+BQ32-BR32) -> 12 | CB32: =SUM(CB31+BY32-BZ32) -> 12 | CJ32: =SUM(CJ31+CG32-CH32) -> 12 | CR32: =SUM(CR31+CO32-CP32) -> 12
H33: =SUM(H32+E33-F33) -> 12 | P33: =SUM(P32+M33-N33) -> 12 | X33: =SUM(X32+U33-V33) -> 12 | AF33: =SUM(AF32+AC33-AD33) -> 12 | AN33: =SUM(AN32+AK33-AL33) -> 12 | AV33: =SUM(AV32+AS33-AT33) -> 12 | BD33: =SUM(BD32+BA33-BB33) -> 12 | BL33: =SUM(BL32+BI33-BJ33) -> 12 | BT33: =SUM(BT32+BQ33-BR33) -> 12 | CB33: =SUM(CB32+BY33-BZ33) -> 12 | CJ33: =SUM(CJ32+CG33-CH33) -> 12 | CR33: =SUM(CR32+CO33-CP33) -> 12
H34: =SUM(H33+E34-F34) -> 12 | P34: =SUM(P33+M34-N34) -> 12 | X34: =SUM(X33+U34-V34) -> 12 | AF34: =SUM(AF33+AC34-AD34) -> 12 | AN34: =SUM(AN33+AK34-AL34) -> 12 | AV34: =SUM(AV33+AS34-AT34) -> 12 | BD34: =SUM(BD33+BA34-BB34) -> 12 | BL34: =SUM(BL33+BI34-BJ34) -> 12 | BT34: =SUM(BT33+BQ34-BR34) -> 12 | CB34: =SUM(CB33+BY34-BZ34) -> 12 | CJ34: =SUM(CJ33+CG34-CH34) -> 12 | CR34: =SUM(CR33+CO34-CP34) -> 12
H35: =SUM(H34+E35-F35) -> 12 | P35: =SUM(P34+M35-N35) -> 12 | X35: =SUM(X34+U35-V35) -> 12 | AF35: =SUM(AF34+AC35-AD35) -> 12 | AN35: =SUM(AN34+AK35-AL35) -> 12 | AV35: =SUM(AV34+AS35-AT35) -> 12 | BD35: =SUM(BD34+BA35-BB35) -> 12 | BL35: =SUM(BL34+BI35-BJ35) -> 12 | BT35: =SUM(BT34+BQ35-BR35) -> 12 | CB35: =SUM(CB34+BY35-BZ35) -> 12 | CJ35: =SUM(CJ34+CG35-CH35) -> 12 | CR35: =SUM(CR34+CO35-CP35) -> 12
H36: =SUM(H35+E36-F36) -> 12 | P36: =SUM(P35+M36-N36) -> 12 | X36: =SUM(X35+U36-V36) -> 12 | AF36: =SUM(AF35+AC36-AD36) -> 12 | AN36: =SUM(AN35+AK36-AL36) -> 12 | AV36: =SUM(AV35+AS36-AT36) -> 12 | BD36: =SUM(BD35+BA36-BB36) -> 12 | BL36: =SUM(BL35+BI36-BJ36) -> 12 | BT36: =SUM(BT35+BQ36-BR36) -> 12 | CB36: =SUM(CB35+BY36-BZ36) -> 12 | CJ36: =SUM(CJ35+CG36-CH36) -> 12 | CR36: =SUM(CR35+CO36-CP36) -> 12
H37: =SUM(H36+E37-F37) -> 12 | P37: =SUM(P36+M37-N37) -> 12 | X37: =SUM(X36+U37-V37) -> 12 | AF37: =SUM(AF36+AC37-AD37) -> 12 | AN37: =SUM(AN36+AK37-AL37) -> 12 | AV37: =SUM(AV36+AS37-AT37) -> 12 | BD37: =SUM(BD36+BA37-BB37) -> 12 | BL37: =SUM(BL36+BI37-BJ37) -> 12 | BT37: =SUM(BT36+BQ37-BR37) -> 12 | CB37: =SUM(CB36+BY37-BZ37) -> 12 | CJ37: =SUM(CJ36+CG37-CH37) -> 12 | CR37: =SUM(CR36+CO37-CP37) -> 12
H38: =SUM(H37+E38-F38) -> 12 | P38: =SUM(P37+M38-N38) -> 12 | X38: =SUM(X37+U38-V38) -> 12 | AF38: =SUM(AF37+AC38-AD38) -> 12 | AN38: =SUM(AN37+AK38-AL38) -> 12 | AV38: =SUM(AV37+AS38-AT38) -> 12 | BD38: =SUM(BD37+BA38-BB38) -> 12 | BL38: =SUM(BL37+BI38-BJ38) -> 12 | BT38: =SUM(BT37+BQ38-BR38) -> 12 | CB38: =SUM(CB37+BY38-BZ38) -> 12 | CJ38: =SUM(CJ37+CG38-CH38) -> 12 | CR38: =SUM(CR37+CO38-CP38) -> 12
B39: Verres (simples) | J39: Verres (simples) | R39: Verres (simples) | Z39: Verres (simples) | AH39: Verres (simples) | AP39: Verres (simples) | AX39: Verres (simples) | BF39: Verres (simples) | BN39: Verres (simples) | BV39: Verres (simples) | CD39: Verres (simples) | CL39: Verres (simples)
E40: Rentree | F40: Sortie | G40: Direction | H40: Balance | M40: Rentree | N40: Sortie | O40: Direction | P40: Balance | U40: Rentree | V40: Sortie | W40: Direction | X40: Balance | AC40: Rentree | AD40: Sortie | AE40: Direction | AF40: Balance | AK40: Rentree | AL40: Sortie | AM40: Direction | AN40: Balance | AS40: Rentree | AT40: Sortie | AU40: Direction | AV40: Balance | BA40: Rentree | BB40: Sortie | BC40: Direction | BD40: Balance | BI40: Rentree | BJ40: Sortie | BK40: Direction | BL40: Balance | BQ40: Rentree | BR40: Sortie | BS40: Direction | BT40: Balance | BY40: Rentree | BZ40: Sortie | CA40: Direction | CB40: Balance | CG40: Rentree | CH40: Sortie | CI40: Direction | CJ40: Balance | CO40: Rentree | CP40: Sortie | CQ40: Direction | CR40: Balance
B41: Balance 30 Sept.22 | E41: Unités | F41: Unités | H41: 6 | J41: Balance 31 Oct. 22 | M41: Unités | N41: Unités | P41: 6 | R41: Balance 30 Nov. 22 | U41: Unités | V41: Unités | X41: 6 | Z41: Balance 31 Déc. 22 | AC41: Unités | AD41: Unités | AF41: 6 | AH41: Balance 31 Jan. 23 | AK41: Unités | AL41: Unités | AN41: 6 | AP41: Balance 28 Fév. 23 | AS41: Unités | AT41: Unités | AV41: 6 | AX41: Balance 31 Mars. 23 | BA41: Unités | BB41: Unités | BD41: 6 | BF41: Balance 30 Avril. 23 | BI41: Unités | BJ41: Unités | BL41: 6 | BN41: Balance 31 Mai. 23 | BQ41: Unités | BR41: Unités | BT41: 6 | BV41: Balance 30 Juin. 23 | BY41: Unités | BZ41: Unités | CB41: 6 | CD41: Balance 31 Juil. 23 | CG41: Unités | CH41: Unités | CJ41: 6 | CL41: Balance 31 Août. 23 | CO41: Unités | CP41: Unités | CR41: 6
H42: =SUM(H41+E42-F42) -> 6 | P42: =SUM(P41+M42-N42) -> 6 | X42: =SUM(X41+U42-V42) -> 6 | AF42: =SUM(AF41+AC42-AD42) -> 6 | AN42: =SUM(AN41+AK42-AL42) -> 6 | AV42: =SUM(AV41+AS42-AT42) -> 6 | BD42: =SUM(BD41+BA42-BB42) -> 6 | BL42: =SUM(BL41+BI42-BJ42) -> 6 | BT42: =SUM(BT41+BQ42-BR42) -> 6 | CB42: =SUM(CB41+BY42-BZ42) -> 6 | CJ42: =SUM(CJ41+CG42-CH42) -> 6 | CR42: =SUM(CR41+CO42-CP42) -> 6
H43: =SUM(H42+E43-F43) -> 6 | P43: =SUM(P42+M43-N43) -> 6 | X43: =SUM(X42+U43-V43) -> 6 | AF43: =SUM(AF42+AC43-AD43) -> 6 | AN43: =SUM(AN42+AK43-AL43) -> 6 | AV43: =SUM(AV42+AS43-AT43) -> 6 | BD43: =SUM(BD42+BA43-BB43) -> 6 | BL43: =SUM(BL42+BI43-BJ43) -> 6 | BT43: =SUM(BT42+BQ43-BR43) -> 6 | CB43: =SUM(CB42+BY43-BZ43) -> 6 | CJ43: =SUM(CJ42+CG43-CH43) -> 6 | CR43: =SUM(CR42+CO43-CP43) -> 6
...

Sheet S
B2: Direction Générale du Budget | J2: Direction Générale du Budget | R2: Direction Générale du Budget | Z2: Direction Générale du Budget | AH2: Direction Générale du Budget | AP2: Direction Générale du Budget | AX2: Direction Générale du Budget | BF2: Direction Générale du Budget | BN2: Direction Générale du Budget | BV2: Direction Générale du Budget | CD2: Direction Générale du Budget | CL2: Direction Générale du Budget
B3: Inventaire stocks fournitures | J3: Inventaire stocks fournitures | R3: Inventaire stocks fournitures | Z3: Inventaire stocks fournitures | AH3: Inventaire stocks fournitures | AP3: Inventaire stocks fournitures | AX3: Inventaire stocks fournitures | BF3: Inventaire stocks fournitures | BN3: Inventaire stocks fournitures | BV3: Inventaire stocks fournitures | CD3: Inventaire stocks fournitures | CL3: Inventaire stocks fournitures
B4: Exercice: 2024-2025 | J4: Exercice: 2024-2025 | R4: Exercice: 2024-2025 | Z4: Exercice: 2024-2025 | AH4: Exercice: 2024-2025 | AP4: Exercice: 2024-2025 | AX4: Exercice: 2024-2025 | BF4: Exercice: 2024-2025 | BN4: Exercice: 2024-2025 | BV4: Exercice: 2024-2025 | CD4: Exercice: 2024-2025 | CL4: Exercice: 2024-2025
B6: 45566 | J6: 45597 | R6: 45627 | Z6: 45658 | AH6: 45689 | AP6: 45717 | AX6: 45748 | BF6: 45778 | BN6: 45809 | BV6: 45839 | CD6: 45870 | CL6: 45536
B8: Produits de nettoyage | J8: Produits de nettoyage | R8: Produits de nettoyage | Z8: Produits de nettoyage | AH8: Produits de nettoyage | AP8: Produits de nettoyage | AX8: Produits de nettoyage | BF8: Produits de nettoyage | BN8: Produits de nettoyage | BV8: Produits de nettoyage | CD8: Produits de nettoyage | CL8: Produits de nettoyage
B10: Air fresh (glade) | J10: Air fresh (glade) | R10: Air fresh (glade) | Z10: Air fresh (glade) | AH10: Air fresh (glade) | AP10: Air fresh (glade) | AX10: Air fresh (glade) | BF10: Air fresh (glade) | BN10: Air fresh (glade) | BV10: Air fresh (glade) | CD10: Air fresh (glade) | CL10: Air fresh (glade)
E11: Rentree | F11: Sortie | G11: Direction | H11: Stock | M11: Rentree | N11: Sortie | O11: Direction | P11: Stock | U11: Rentree | V11: Sortie | W11: Direction | X11: Stock | AC11: Rentree | AD11: Sortie | AE11: Direction | AF11: Stock | AK11: Rentree | AL11: Sortie | AM11: Direction | AN11: Stock | AS11: Rentree | AT11: Sortie | AU11: Direction | AV11: Stock | BA11: Rentree | BB11: Sortie | BC11: Direction | BD11: Stock | BI11: Rentree | BJ11: Sortie | BK11: Direction | BL11: Stock | BQ11: Rentree | BR11: Sortie | BS11: Direction | BT11: Stock | BY11: Rentree | BZ11: Sortie | CA11: Direction | CB11: Stock | CG11: Rentree | CH11: Sortie | CI11: Direction | CJ11: Stock | CO11: Rentree | CP11: Sortie | CQ11: Direction | CR11: Stock
B12: Stock 30 Sept.24 | E12: Unités | F12: Unités | H12: 19 | J12: Stock 31 Oct. 24 | M12: Unités | N12: Unités | P12: 14 | R12: Stock 30 Nov. 24 | U12: Unités | V12: Unités | X12: 12 | Z12: Stock 31 Déc. 24 | AC12: Unités | AD12: Unités | AF12: 21 | AH12: Stock 31 Jan. 25 | AK12: Unités | AL12: Unités | AN12: 15 | AP12: Stock 28 Fév. 25 | AS12: Unités | AT12: Unités | AV12: 9 | AX12: Stock 31 Mars. 25 | BA12: Unités | BB12: Unités | BD12: 7 | BF12: Stock 30 Avril. 25 | BI12: Unités | BJ12: Unités | BL12: 28 | BN12: Stock 31 Mai. 25 | BQ12: Unités | BR12: Unités | BT12: =BL19 -> 19 | BV12: Stock 30 Juin. 25 | BY12: Unités | BZ12: Unités | CB12: =BT18 -> 12 | CD12: Stock 31 Juil. 25 | CG12: Unités | CH12: Unités | CJ12: =CB17 -> 8 | CL12: Stock 31 Août. 24 | CO12: Unités | CP12: Unités | CR12: =CJ18 -> 1
B13: 45574 | E13: 0 | F13: 1 | G13: DG | H13: =SUM(H12+E13-F13) -> 18 | J13: 45605 | M13: 0 | N13: 1 | O13: DAA | P13: =SUM(P12+M13-N13) -> 13 | R13: 45629 | U13: 0 | V13: 2 | W13: DAA | X13: =SUM(X12+U13-V13) -> 10 | Z13: 45661 | AC13: 0 | AD13: 1 | AE13: DAA | AF13: =SUM(AF12+AC13-AD13) -> 20 | AH13: 45689 | AK13: 0 | AL13: 1 | AM13: DAA | AN13: =SUM(AN12+AK13-AL13) -> 14 | AP13: 45724 | AT13: 2 | AU13: DAA | AV13: =SUM(AV12+AS14-AT13) -> 7 | AX13: 45758 | BA13: 0 | BB13: 1 | BC13: DEPB | BD13: =SUM(BD12+BA13-BB13) -> 6 | BF13: 45780 | BI13: 0 | BJ13: 1 | BK13: DAA | BL13: =SUM(BL12+BI13-BJ13) -> 27 | BN13: 45814 | BQ13: 0 | BR13: 2 | BS13: DG | BT13: =SUM(BT12+BQ13-BR13) -> 17 | BV13: 189 | BY13: 0 | BZ13: 1 | CA13: DAA | CB13: =SUM(CB12+BY13-BZ13) -> 11 | CD13: 45870 | CG13: 0 | CH13: 2 | CI13: DAA | CJ13: =SUM(CJ12+CG13-CH13) -> 6 | CR13: =SUM(CR12+CO13-CP13) -> 1
B14: 45575 | E14: 0 | F14: 1 | G14: DAA | H14: =SUM(H13+E14-F14) -> 17 | J14: 45609 | M14: 0 | N14: 1 | O14: DG | P14: =SUM(P13+M14-N14) -> 12 | R14: 45637 | U14: 14 | V14: 0 | W14: DAA | X14: =SUM(X13+U14-V14) -> 24 | Z14: 45663 | AC14: 0 | AD14: 1 | AE14: DG | AF14: =SUM(AF13+AC14-AD14) -> 19 | AH14: 45693 | AK14: 0 | AL14: 1 | AM14: DG | AN14: =SUM(AN13+AK14-AL14) -> 13 | AP14: 45731 | AS14: 0 | AT14: 2 | AU14: DAA | AV14: =SUM(AV13+AS15-AT14) -> 5 | AX14: 45762 | BA14: 24 | BB14: 0 | BC14: DAA | BD14: =SUM(BD13+BA14-BB14) -> 30 | BF14: 45782 | BI14: 0 | BJ14: 1 | BK14: DAA | BL14: =SUM(BL13+BI14-BJ14) -> 26 | BN14: 45818 | BQ14: 0 | BR14: 2 | BS14: DAA | BT14: =SUM(BT13+BQ14-BR14) -> 15 | BV14: 194 | BY14: 0 | BZ14: 1 | CA14: DG | CB14: =SUM(CB13+BY14-BZ14) -> 10 | CD14: 45877 | CG14: 0 | CH14: 1 | CI14: DG | CJ14: =SUM(CJ13+CG14-CH14) -> 5 | CR14: =SUM(CR13+CO14-CP14) -> 1
B15: 45577 | E15: 0 | F15: 1 | G15: DAA | H15: =SUM(H14+E15-F15) -> 16 | P15: =SUM(P14+M15-N15) -> 12 | R15: 45640 | U15: 0 | V15: 2 | W15: DAA | X15: =SUM(X14+U15-V15) -> 22 | Z15: 45667 | AC15: 0 | AD15: 1 | AE15: DAA | AF15: =SUM(AF14+AC15-AD15) -> 18 | AH15: 45696 | AK15: 0 | AL15: 1 | AM15: DAA | AN15: =SUM(AN14+AK15-AL15) -> 12 | AP15: 45734 | AS15: 0 | AT15: 1 | AU15: DG | AV15: =SUM(AV14+AS15-AT15) -> 4 | AX15: 45764 | BA15: 0 | BB15: 1 | BC15: DAA | BD15: =SUM(BD14+BA15-BB15) -> 29 | BF15: 45784 | BI15: 0 | BJ15: 1 | BK15: DG | BL15: =SUM(BL14+BI15-BJ15) -> 25 | BN15: 45820 | BQ15: 0 | BR15: 1 | BS15: DCB | BT15: =SUM(BT14+BQ15-BR15) -> 14 | BV15: 197 | BY15: 0 | BZ15: 1 | CA15: DAA | CB15: =SUM(CB14+BY15-BZ15) -> 9 | CD15: 45877 | CG15: 0 | CH15: 1 | CI15: DAA | CJ15: =SUM(CJ14+CG15-CH15) -> 4 | CR15: =SUM(CR14+CO15-CP15) -> 1
B16: 45584 | E16: 0 | F16: 1 | G16: DAA | H16: =SUM(H15+E16-F16) -> 15 | P16: =SUM(P15+M16-N16) -> 12 | R16: 45652 | U16: 0 | V16: 1 | W16: DAA | X16: =SUM(X15+U16-V16) -> 21 | Z16: 45673 | AC16: 0 | AD16: 1 | AE16: DAA | AF16: =SUM(AF15+AC16-AD16) -> 17 | AH16: 45703 | AK16: 0 | AL16: 1 | AM16: DAA | AN16: =SUM(AN15+AK16-AL16) -> 11 | AV16: =SUM(AV15+AS16-AT16) -> 4 | AX16: 45768 | BA16: 0 | BB16: 1 | BC16: DAA | BD16: =SUM(BD15+BA16-BB16) -> 28 | BF16: 45791 | BI16: 0 | BJ16: 1 | BK16: DS | BL16: =SUM(BL15+BI16-BJ16) -> 24 | BN16: 45826 | BQ16: 0 | BR16: 1 | BS16: DS | BT16: =SUM(BT15+BQ16-BR16) -> 13 | BV16: 45862 | BY16: 0 | BZ16: 1 | CA16: DAA | CB16: =SUM(CB15+BY16-BZ16) -> 8 | CD16: 45887 | CG16: 0 | CH16: 1 | CI16: DAA | CJ16: =SUM(CJ15+CG16-CH16) -> 3 | CR16: =SUM(CR15+CO16-CP16) -> 1
B17: 45587 | E17: 0 | F17: 1 | G17: DAA | H17: =SUM(H16+E17-F17) -> 14 | P17: =SUM(P16+M17-N17) -> 12 | X17: =SUM(X16+U17-V17) -> 21 | Z17: 45672 | AC17: 0 | AD17: 1 | AE17: DAA | AF17: =SUM(AF16+AC17-AD17) -> 16 | AH17: 45707 | AK17: 0 | AL17: 1 | AM17: DG | AN17: =SUM(AN16+AK17-AL17) -> 10 | AV17: =SUM(AV16+AS17-AT17) -> 4 | BD17: =SUM(BD16+BA17-BB17) -> 28 | BF17: 45803 | BI17: 0 | BJ17: 4 | BK17: DAA | BL17: =SUM(BL16+BI17-BJ17) -> 20 | BN17: 45834 | BQ17: 0 | BR17: 1 | BS17: DAA | BT17: =SUM(BT16+BQ17-BR17) -> 12 | CB17: =SUM(CB16+BY17-BZ17) -> 8 | CD17: 45889 | CG17: 0 | CH17: 1 | CI17: DAA | CJ17: =SUM(CJ16+CG17-CH17) -> 2 | CR17: =SUM(CR16+CO17-CP17) -> 1
H18: =SUM(H17+E18-F18) -> 14 | P18: =SUM(P17+M18-N18) -> 12 | X18: =SUM(X17+U18-V18) -> 21 | Z18: 45679 | AC18: 0 | AD18: 1 | AE18: DAA | AF18: =SUM(AF17+AC18-AD18) -> 15 | AH18: 45710 | AK18: 0 | AL18: 1 | AM18: DAA | AN18: =SUM(AN17+AK18-AL18) -> 9 | AV18: =SUM(AV17+AS18-AT18) -> 4 | BD18: =SUM(BD17+BA18-BB18) -> 28 | BF18: 45799 | BI18: 0 | BJ18: 1 | BK18: DG | BL18: =SUM(BL17+BI18-BJ18) -> 19 | BT18: =SUM(BT17+BQ18-BR18) -> 12 | CB18: =SUM(CB17+BY18-BZ18) -> 8 | CD18: 45896 | CG18: 0 | CH18: 1 | CI18: DAA | CJ18: =SUM(CJ17+CG18-CH18) -> 1 | CR18: =SUM(CR17+CO18-CP18) -> 1
H19: =SUM(H18+E19-F19) -> 14 | P19: =SUM(P18+M19-N19) -> 12 | X19: =SUM(X18+U19-V19) -> 21 | AF19: =SUM(AF18+AC19-AD19) -> 15 | AN19: =SUM(AN18+AK19-AL19) -> 9 | AV19: =SUM(AV18+AS19-AT19) -> 4 | BD19: =SUM(BD18+BA19-BB19) -> 28 | BL19: =SUM(BL18+BI19-BJ19) -> 19 | BT19: =SUM(BT18+BQ19-BR19) -> 12 | CB19: =SUM(CB18+BY19-BZ19) -> 8 | CJ19: =SUM(CJ18+CG19-CH19) -> 1 | CR19: =SUM(CR18+CO19-CP19) -> 1
H20: =SUM(H19+E20-F20) -> 14 | P20: =SUM(P19+M20-N20) -> 12 | X20: =SUM(X19+U20-V20) -> 21 | AF20: =SUM(AF19+AC20-AD20) -> 15 | AN20: =SUM(AN19+AK20-AL20) -> 9 | AV20: =SUM(AV19+AS20-AT20) -> 4 | BD20: =SUM(BD19+BA20-BB20) -> 28 | BL20: =SUM(BL19+BI20-BJ20) -> 19 | BT20: =SUM(BT19+BQ20-BR20) -> 12 | CB20: =SUM(CB19+BY20-BZ20) -> 8 | CJ20: =SUM(CJ19+CG20-CH20) -> 1 | CR20: =SUM(CR19+CO20-CP20) -> 1
H21: =SUM(H20+E21-F21) -> 14 | P21: =SUM(P20+M21-N21) -> 12 | X21: =SUM(X20+U21-V21) -> 21 | AF21: =SUM(AF20+AC21-AD21) -> 15 | AN21: =SUM(AN20+AK21-AL21) -> 9 | AV21: =SUM(AV20+AS21-AT21) -> 4 | BD21: =SUM(BD20+BA21-BB21) -> 28 | BL21: =SUM(BL20+BI21-BJ21) -> 19 | BT21: =SUM(BT20+BQ21-BR21) -> 12 | CB21: =SUM(CB20+BY21-BZ21) -> 8 | CJ21: =SUM(CJ20+CG21-CH21) -> 1 | CR21: =SUM(CR20+CO21-CP21) -> 1
H22: =SUM(H21+E22-F22) -> 14 | P22: =SUM(P21+M22-N22) -> 12 | X22: =SUM(X21+U22-V22) -> 21 | AF22: =SUM(AF21+AC22-AD22) -> 15 | AN22: =SUM(AN21+AK22-AL22) -> 9 | AV22: =SUM(AV21+AS22-AT22) -> 4 | BD22: =SUM(BD21+BA22-BB22) -> 28 | BL22: =SUM(BL21+BI22-BJ22) -> 19 | BT22: =SUM(BT21+BQ22-BR22) -> 12 | CB22: =SUM(CB21+BY22-BZ22) -> 8 | CJ22: =SUM(CJ21+CG22-CH22) -> 1 | CR22: =SUM(CR21+CO22-CP22) -> 1
B23: Acide | J23: Acide | R23: Acide | Z23: Acide | AH23: Acide | AP23: Acide | AX23: Acide | BF23: Acide | BN23: Acide | BV23: Acide | CD23: Acide | CL23: Acide
E24: Rentree | F24: Sortie | G24: Direction | H24: Stock | M24: Rentree | N24: Sortie | O24: Direction | P24: Stock | U24: Rentree | V24: Sortie | W24: Direction | X24: Stock | AC24: Rentree | AD24: Sortie | AE24: Direction | AF24: Stock | AK24: Rentree | AL24: Sortie | AM24: Direction | AN24: Stock | AS24: Rentree | AT24: Sortie | AU24: Direction | AV24: Stock | BA24: Rentree | BB24: Sortie | BC24: Direction | BD24: Stock | BI24: Rentree | BJ24: Sortie | BK24: Direction | BL24: Stock | BQ24: Rentree | BR24: Sortie | BS24: Direction | BT24: Stock | BY24: Rentree | BZ24: Sortie | CA24: Direction | CB24: Stock | CG24: Rentree | CH24: Sortie | CI24: Direction | CJ24: Stock | CO24: Rentree | CP24: Sortie | CQ24: Direction | CR24: Stock
B25: Stock 30 Sept.24 | E25: gallons | F25: gallons | H25: 6 | J25: Stock 31 Oct. 24 | M25: gallons | N25: gallons | P25: 6 | R25: Stock 30 Nov. 24 | U25: gallons | V25: gallons | X25: 5 | Z25: Stock 31 Déc. 24 | AC25: gallons | AD25: gallons | AF25: 4 | AH25: Stock 31 Jan. 25 | AK25: gallons | AL25: gallons | AN25: 4 | AP25: Stock 28 Fév. 25 | AS25: gallons | AT25: gallons | AV25: 4 | AX25: Stock 31 Mars. 25 | BA25: gallons | BB25: gallons | BD25: 4 | BF25: Stock 30 Avril. 25 | BI25: gallons | BJ25: gallons | BL25: 4 | BN25: Stock 31 Mai. 25 | BQ25: gallons | BR25: gallons | BT25: 4 | BV25: Stock 30 Juin. 25 | BY25: gallons | BZ25: gallons | CB25: 2 | CD25: Stock 31 Juil. 25 | CG25: gallons | CH25: gallons | CJ25: =CB26 -> 2 | CL25: Stock 31 Août. 24 | CO25: gallons | CP25: gallons | CR25: 0
H26: =SUM(H25+E26-F26) -> 6 | J26: 45618 | M26: 0 | N26: 1 | O26: DAA | P26: =SUM(P25+M26-N26) -> 5 | R26: 45640 | U26: 0 | V26: 1 | W26: DAA | X26: =SUM(X25+U26-V26) -> 4 | AF26: =SUM(AF25+AC26-AD26) -> 4 | AN26: =SUM(AN25+AK26-AL26) -> 4 | AV26: =SUM(AV25+AS26-AT26) -> 4 | BD26: =SUM(BD25+BA26-BB26) -> 4 | BL26: =SUM(BL25+BI26-BJ26) -> 4 | BN26: 45818 | BQ26: 0 | BR26: 1 | BS26: DAA | BT26: =SUM(BT25+BQ26-BR26) -> 3 | CB26: =SUM(CB25+BY26-BZ26) -> 2 | CD26: 45870 | CG26: 0 | CH26: 1 | CI26: DAA | CJ26: =SUM(CJ25+CG26-CH26) -> 1 | CR26: =SUM(CR25+CO26-CP26) -> 0
H27: =SUM(H26+E27-F27) -> 6 | P27: =SUM(P26+M27-N27) -> 5 | X27: =SUM(X26+U27-V27) -> 4 | AF27: =SUM(AF26+AC27-AD27) -> 4 | AN27: =SUM(AN26+AK27-AL27) -> 4 | AV27: =SUM(AV26+AS27-AT27) -> 4 | BD27: =SUM(BD26+BA27-BB27) -> 4 | BL27: =SUM(BL26+BI27-BJ27) -> 4 | BN27: 45833 | BQ27: 0 | BR27: 1 | BS27: DAA | BT27: =SUM(BT26+BQ27-BR27) -> 2 | CB27: =SUM(CB26+BY27-BZ27) -> 2 | CD27: 45900 | CG27: 0 | CH27: 1 | CI27: DAA | CJ27: =SUM(CJ26+CG27-CH27) -> 0 | CR27: =SUM(CR26+CO27-CP27) -> 0
H28: =SUM(H27+E28-F28) -> 6 | P28: =SUM(P27+M28-N28) -> 5 | X28: =SUM(X27+U28-V28) -> 4 | AF28: =SUM(AF27+AC28-AD28) -> 4 | AN28: =SUM(AN27+AK28-AL28) -> 4 | AV28: =SUM(AV27+AS28-AT28) -> 4 | BD28: =SUM(BD27+BA28-BB28) -> 4 | BL28: =SUM(BL27+BI28-BJ28) -> 4 | BT28: =SUM(BT27+BQ28-BR28) -> 2 | CB28: =SUM(CB27+BY28-BZ28) -> 2 | CJ28: =SUM(CJ27+CG28-CH28) -> 0 | CR28: =SUM(CR27+CO28-CP28) -> 0
H29: =SUM(H28+E29-F29) -> 6 | P29: =SUM(P28+M29-N29) -> 5 | X29: =SUM(X28+U29-V29) -> 4 | AF29: =SUM(AF28+AC29-AD29) -> 4 | AN29: =SUM(AN28+AK29-AL29) -> 4 | AV29: =SUM(AV28+AS29-AT29) -> 4 | BD29: =SUM(BD28+BA29-BB29) -> 4 | BL29: =SUM(BL28+BI29-BJ29) -> 4 | BT29: =SUM(BT28+BQ29-BR29) -> 2 | CB29: =SUM(CB28+BY29-BZ29) -> 2 | CJ29: =SUM(CJ28+CG29-CH29) -> 0 | CR29: =SUM(CR28+CO29-CP29) -> 0
H30: =SUM(H29+E30-F30) -> 6 | P30: =SUM(P29+M30-N30) -> 5 | X30: =SUM(X29+U30-V30) -> 4 | AF30: =SUM(AF29+AC30-AD30) -> 4 | AN30: =SUM(AN29+AK30-AL30) -> 4 | AV30: =SUM(AV29+AS30-AT30) -> 4 | BD30: =SUM(BD29+BA30-BB30) -> 4 | BL30: =SUM(BL29+BI30-BJ30) -> 4 | BT30: =SUM(BT29+BQ30-BR30) -> 2 | CB30: =SUM(CB29+BY30-BZ30) -> 2 | CJ30: =SUM(CJ29+CG30-CH30) -> 0 | CR30: =SUM(CR29+CO30-CP30) -> 0
